<?xml version="1.0" ?>
<!-- =================================================================================== -->
<!-- |    This document was autogenerated by xacro from scotty_final.urdf.xacro        | -->
<!-- |    EDITING THIS FILE BY HAND IS NOT RECOMMENDED                                 | -->
<!-- =================================================================================== -->
<robot name="scotty_robot" xmlns:xacro="http://ros.org/wiki/xacro">
  <link name="base_link">
    <inertial>
      <origin rpy="0 0 0" xyz="0 0 0.02"/>
      <mass value="6.03"/>
      <inertia ixx="0.04" ixy="0" ixz="0" iyy="0.24" iyz="0" izz="0.27"/>
    </inertial>
    <visual>
      <origin rpy="0 0 0" xyz="0 0 0"/>
      <geometry>
        <mesh filename="package://scotty_description/meshes/base_link.STL"/>
      </geometry>
      <material name="">
        <color rgba="0.89804 0.91765 0.92941 1"/>
      </material>
    </visual>
    <collision>
      <origin rpy="0 0 0" xyz="0 0 0"/>
      <geometry>
        <mesh filename="package://scotty_description/meshes/base_link.STL"/>
      </geometry>
    </collision>
  </link>
  <link name="abad_FR_link">
    <inertial>
      <origin rpy="0 0 0" xyz="0.06 0 0"/>
      <mass value="1.03"/>
      <inertia ixx="0" ixy="0" ixz="0" iyy="0" iyz="0" izz="0"/>
    </inertial>
    <visual>
      <origin rpy="0 0 0" xyz="0 0 0"/>
      <geometry>
        <mesh filename="package://scotty_description/meshes/abad_FR_link.STL"/>
      </geometry>
      <material name="">
        <color rgba="0.29804 0.29804 0.29804 1"/>
      </material>
    </visual>
    <collision>
      <origin rpy="0 0 0" xyz="0 0 0"/>
      <geometry>
        <mesh filename="package://scotty_description/meshes/abad_FR_link.STL"/>
      </geometry>
    </collision>
  </link>
  <joint name="abad_FR_joint" type="revolute">
    <origin rpy="0 0 0" xyz="0.2485 -0.065 0.025"/>
    <parent link="base_link"/>
    <child link="abad_FR_link"/>
    <axis xyz="1 0 0"/>
    <limit effort="25" lower="-0.65" upper="0.65" velocity="3"/>
  </joint>
  <link name="hip_FR_link">
    <inertial>
      <origin rpy="0 0 0" xyz="0 -0.06 -0.04"/>
      <mass value="1.74"/>
      <inertia ixx="0.01" ixy="0" ixz="0" iyy="0.01" iyz="0" izz="0"/>
    </inertial>
    <visual>
      <origin rpy="0 0 0" xyz="0 0 0"/>
      <geometry>
        <mesh filename="package://scotty_description/meshes/hip_FR_link.STL"/>
      </geometry>
      <material name="">
        <color rgba="0.29804 0.29804 0.29804 1"/>
      </material>
    </visual>
    <collision>
      <origin rpy="0 0 0" xyz="0 0 0"/>
      <geometry>
        <mesh filename="package://scotty_description/meshes/hip_FR_link.STL"/>
      </geometry>
    </collision>
  </link>
  <joint name="hip_FR_joint" type="revolute">
    <origin rpy="0 0 0" xyz="0.065 -0.03 0"/>
    <parent link="abad_FR_link"/>
    <child link="hip_FR_link"/>
    <axis xyz="0 1 0"/>
    <limit effort="50" lower="-1.25" upper="1.8" velocity="3"/>
  </joint>
  <link name="knee_FR_link">
    <inertial>
      <origin rpy="0 0 0" xyz="0.01 0 -0.1"/>
      <mass value="0.52"/>
      <inertia ixx="0.01" ixy="0" ixz="0" iyy="0.01" iyz="0" izz="0"/>
    </inertial>
    <visual>
      <origin rpy="0 0 0" xyz="0 0 0"/>
      <geometry>
        <mesh filename="package://scotty_description/meshes/knee_FR_link.STL"/>
      </geometry>
      <material name="">
        <color rgba="0.89804 0.91765 0.92941 1"/>
      </material>
    </visual>
    <collision>
      <origin rpy="0 0 0" xyz="0 0 0"/>
      <geometry>
        <mesh filename="package://scotty_description/meshes/knee_FR_link.STL"/>
      </geometry>
    </collision>
  </link>
  <joint name="knee_FR_joint" type="revolute">
    <origin rpy="0 0 0" xyz="0 -0.087405 -0.3"/>
    <parent link="hip_FR_link"/>
    <child link="knee_FR_link"/>
    <axis xyz="0 1 0"/>
    <limit effort="50" lower="-2.5" upper="0" velocity="3"/>
  </joint>
  <link name="foot_FR_link">
    <inertial>
      <origin rpy="0 0 0" xyz="0 0 0"/>
      <mass value="0.02"/>
      <inertia ixx="0" ixy="0" ixz="0" iyy="0" iyz="0" izz="0"/>
    </inertial>
    <visual>
      <origin rpy="0 0 0" xyz="0 0 0"/>
      <geometry>
        <mesh filename="package://scotty_description/meshes/foot_FR_link.STL"/>
      </geometry>
      <material name="">
        <color rgba="0.29804 0.29804 0.29804 1"/>
      </material>
    </visual>
    <collision>
      <origin rpy="0 0 0" xyz="0 0 0"/>
      <geometry>
        <mesh filename="package://scotty_description/meshes/foot_FR_link.STL"/>
      </geometry>
    </collision>
  </link>
  <joint name="foot_FR_joint" type="fixed">
    <origin rpy="0 0 0" xyz="0.0175 0.001605 -0.3"/>
    <parent link="knee_FR_link"/>
    <child link="foot_FR_link"/>
    <axis xyz="0 0 0"/>
  </joint>
  <link name="abad_FL_link">
    <inertial>
      <origin rpy="0 0 0" xyz="0.06 0 0"/>
      <mass value="1.03"/>
      <inertia ixx="0" ixy="0" ixz="0" iyy="0" iyz="0" izz="0"/>
    </inertial>
    <visual>
      <origin rpy="0 0 0" xyz="0 0 0"/>
      <geometry>
        <mesh filename="package://scotty_description/meshes/abad_FL_link.STL"/>
      </geometry>
      <material name="">
        <color rgba="0.75294 0.75294 0.75294 1"/>
      </material>
    </visual>
    <collision>
      <origin rpy="0 0 0" xyz="0 0 0"/>
      <geometry>
        <mesh filename="package://scotty_description/meshes/abad_FL_link.STL"/>
      </geometry>
    </collision>
  </link>
  <joint name="abad_FL_joint" type="revolute">
    <origin rpy="0 0 0" xyz="0.2485 0.065 0.025"/>
    <parent link="base_link"/>
    <child link="abad_FL_link"/>
    <axis xyz="1 0 0"/>
    <limit effort="25" lower="-0.65" upper="0.65" velocity="3"/>
  </joint>
  <link name="hip_FL_link">
    <inertial>
      <origin rpy="0 0 0" xyz="0 0.06 -0.04"/>
      <mass value="1.74"/>
      <inertia ixx="0.01" ixy="0" ixz="0" iyy="0.01" iyz="0" izz="0"/>
    </inertial>
    <visual>
      <origin rpy="0 0 0" xyz="0 0 0"/>
      <geometry>
        <mesh filename="package://scotty_description/meshes/hip_FL_link.STL"/>
      </geometry>
      <material name="">
        <color rgba="0.29804 0.29804 0.29804 1"/>
      </material>
    </visual>
    <collision>
      <origin rpy="0 0 0" xyz="0 0 0"/>
      <geometry>
        <mesh filename="package://scotty_description/meshes/hip_FL_link.STL"/>
      </geometry>
    </collision>
  </link>
  <joint name="hip_FL_joint" type="revolute">
    <origin rpy="0 0 0" xyz="0.065 0.03 0"/>
    <parent link="abad_FL_link"/>
    <child link="hip_FL_link"/>
    <axis xyz="0 1 0"/>
    <limit effort="50" lower="-1.25" upper="1.8" velocity="3"/>
  </joint>
  <link name="knee_FL_link">
    <inertial>
      <origin rpy="0 0 0" xyz="0.01 0 -0.1"/>
      <mass value="0.52"/>
      <inertia ixx="0.01" ixy="0" ixz="0" iyy="0.01" iyz="0" izz="0"/>
    </inertial>
    <visual>
      <origin rpy="0 0 0" xyz="0 0 0"/>
      <geometry>
        <mesh filename="package://scotty_description/meshes/knee_FL_link.STL"/>
      </geometry>
      <material name="">
        <color rgba="0.89804 0.91765 0.92941 1"/>
      </material>
    </visual>
    <collision>
      <origin rpy="0 0 0" xyz="0 0 0"/>
      <geometry>
        <mesh filename="package://scotty_description/meshes/knee_FL_link.STL"/>
      </geometry>
    </collision>
  </link>
  <joint name="knee_FL_joint" type="revolute">
    <origin rpy="0 0 0" xyz="0 0.087405 -0.3"/>
    <parent link="hip_FL_link"/>
    <child link="knee_FL_link"/>
    <axis xyz="0 1 0"/>
    <limit effort="50" lower="-2.5" upper="0" velocity="3"/>
  </joint>
  <link name="foot_FL_link">
    <inertial>
      <origin rpy="0 0 0" xyz="0 0 0"/>
      <mass value="0.02"/>
      <inertia ixx="0" ixy="0" ixz="0" iyy="0" iyz="0" izz="0"/>
    </inertial>
    <visual>
      <origin rpy="0 0 0" xyz="0 0 0"/>
      <geometry>
        <mesh filename="package://scotty_description/meshes/foot_FL_link.STL"/>
      </geometry>
      <material name="">
        <color rgba="0.29804 0.29804 0.29804 1"/>
      </material>
    </visual>
    <collision>
      <origin rpy="0 0 0" xyz="0 0 0"/>
      <geometry>
        <mesh filename="package://scotty_description/meshes/foot_FL_link.STL"/>
      </geometry>
    </collision>
  </link>
  <joint name="foot_FL_joint" type="fixed">
    <origin rpy="0 0 0" xyz="0.0175 0.004395 -0.3"/>
    <parent link="knee_FL_link"/>
    <child link="foot_FL_link"/>
    <axis xyz="0 0 0"/>
  </joint>
  <link name="abad_RR_link">
    <inertial>
      <origin rpy="0 0 0" xyz="-0.06 0 0"/>
      <mass value="1.03"/>
      <inertia ixx="0" ixy="0" ixz="0" iyy="0" iyz="0" izz="0"/>
    </inertial>
    <visual>
      <origin rpy="0 0 0" xyz="0 0 0"/>
      <geometry>
        <mesh filename="package://scotty_description/meshes/abad_RR_link.STL"/>
      </geometry>
      <material name="">
        <color rgba="0.75294 0.75294 0.75294 1"/>
      </material>
    </visual>
    <collision>
      <origin rpy="0 0 0" xyz="0 0 0"/>
      <geometry>
        <mesh filename="package://scotty_description/meshes/abad_RR_link.STL"/>
      </geometry>
    </collision>
  </link>
  <joint name="abad_RR_joint" type="revolute">
    <origin rpy="0 0 0" xyz="-0.2485 -0.065 0.025"/>
    <parent link="base_link"/>
    <child link="abad_RR_link"/>
    <axis xyz="1 0 0"/>
    <limit effort="25" lower="-0.65" upper="0.65" velocity="3"/>
  </joint>
  <link name="hip_RR_link">
    <inertial>
      <origin rpy="0 0 0" xyz="0 -0.06 -0.04"/>
      <mass value="1.74"/>
      <inertia ixx="0.01" ixy="0" ixz="0" iyy="0.01" iyz="0" izz="0"/>
    </inertial>
    <visual>
      <origin rpy="0 0 0" xyz="0 0 0"/>
      <geometry>
        <mesh filename="package://scotty_description/meshes/hip_RR_link.STL"/>
      </geometry>
      <material name="">
        <color rgba="0.75294 0.75294 0.75294 1"/>
      </material>
    </visual>
    <collision>
      <origin rpy="0 0 0" xyz="0 0 0"/>
      <geometry>
        <mesh filename="package://scotty_description/meshes/hip_RR_link.STL"/>
      </geometry>
    </collision>
  </link>
  <joint name="hip_RR_joint" type="revolute">
    <origin rpy="0 0 0" xyz="-0.065 -0.03 0"/>
    <parent link="abad_RR_link"/>
    <child link="hip_RR_link"/>
    <axis xyz="0 1 0"/>
    <limit effort="50" lower="-1.25" upper="1.8" velocity="3"/>
  </joint>
  <link name="knee_RR_link">
    <inertial>
      <origin rpy="0 0 0" xyz="0.01 0 -0.1"/>
      <mass value="0.52"/>
      <inertia ixx="0.01" ixy="0" ixz="0" iyy="0.01" iyz="0" izz="0"/>
    </inertial>
    <visual>
      <origin rpy="0 0 0" xyz="0 0 0"/>
      <geometry>
        <mesh filename="package://scotty_description/meshes/knee_RR_link.STL"/>
      </geometry>
      <material name="">
        <color rgba="0.89804 0.91765 0.92941 1"/>
      </material>
    </visual>
    <collision>
      <origin rpy="0 0 0" xyz="0 0 0"/>
      <geometry>
        <mesh filename="package://scotty_description/meshes/knee_RR_link.STL"/>
      </geometry>
    </collision>
  </link>
  <joint name="knee_RR_joint" type="revolute">
    <origin rpy="0 0 0" xyz="0 -0.087405 -0.3"/>
    <parent link="hip_RR_link"/>
    <child link="knee_RR_link"/>
    <axis xyz="0 1 0"/>
    <limit effort="50" lower="-2.5" upper="0" velocity="3"/>
  </joint>
  <link name="foot_RR_link">
    <inertial>
      <origin rpy="0 0 0" xyz="0 0 0"/>
      <mass value="0.02"/>
      <inertia ixx="0" ixy="0" ixz="0" iyy="0" iyz="0" izz="0"/>
    </inertial>
    <visual>
      <origin rpy="0 0 0" xyz="0 0 0"/>
      <geometry>
        <mesh filename="package://scotty_description/meshes/foot_RR_link.STL"/>
      </geometry>
      <material name="">
        <color rgba="0.29804 0.29804 0.29804 1"/>
      </material>
    </visual>
    <collision>
      <origin rpy="0 0 0" xyz="0 0 0"/>
      <geometry>
        <mesh filename="package://scotty_description/meshes/foot_RR_link.STL"/>
      </geometry>
    </collision>
  </link>
  <joint name="foot_RR_joint" type="fixed">
    <origin rpy="0 0 0" xyz="0.0175 0.001605 -0.3"/>
    <parent link="knee_RR_link"/>
    <child link="foot_RR_link"/>
    <axis xyz="0 0 0"/>
  </joint>
  <link name="abad_RL_link">
    <inertial>
      <origin rpy="0 0 0" xyz="-0.06 0 0"/>
      <mass value="1.03"/>
      <inertia ixx="0" ixy="0" ixz="0" iyy="0" iyz="0" izz="0"/>
    </inertial>
    <visual>
      <origin rpy="0 0 0" xyz="0 0 0"/>
      <geometry>
        <mesh filename="package://scotty_description/meshes/abad_RL_link.STL"/>
      </geometry>
      <material name="">
        <color rgba="1 1 1 1"/>
      </material>
    </visual>
    <collision>
      <origin rpy="0 0 0" xyz="0 0 0"/>
      <geometry>
        <mesh filename="package://scotty_description/meshes/abad_RL_link.STL"/>
      </geometry>
    </collision>
  </link>
  <joint name="abad_RL_joint" type="revolute">
    <origin rpy="0 0 0" xyz="-0.2485 0.065 0.025"/>
    <parent link="base_link"/>
    <child link="abad_RL_link"/>
    <axis xyz="1 0 0"/>
    <limit effort="25" lower="-0.65" upper="0.65" velocity="3"/>
  </joint>
  <link name="hip_RL_link">
    <inertial>
      <origin rpy="0 0 0" xyz="0 0.06 -0.04"/>
      <mass value="1.74"/>
      <inertia ixx="0.01" ixy="0" ixz="0" iyy="0.01" iyz="0" izz="0"/>
    </inertial>
    <visual>
      <origin rpy="0 0 0" xyz="0 0 0"/>
      <geometry>
        <mesh filename="package://scotty_description/meshes/hip_RL_link.STL"/>
      </geometry>
      <material name="">
        <color rgba="0.29804 0.29804 0.29804 1"/>
      </material>
    </visual>
    <collision>
      <origin rpy="0 0 0" xyz="0 0 0"/>
      <geometry>
        <mesh filename="package://scotty_description/meshes/hip_RL_link.STL"/>
      </geometry>
    </collision>
  </link>
  <joint name="hip_RL_joint" type="revolute">
    <origin rpy="0 0 0" xyz="-0.065 0.03 0"/>
    <parent link="abad_RL_link"/>
    <child link="hip_RL_link"/>
    <axis xyz="0 1 0"/>
    <limit effort="50" lower="-1.25" upper="1.8" velocity="3"/>
  </joint>
  <link name="knee_RL_link">
    <inertial>
      <origin rpy="0 0 0" xyz="0.01 0 -0.1"/>
      <mass value="0.52"/>
      <inertia ixx="0.01" ixy="0" ixz="0" iyy="0.01" iyz="0" izz="0"/>
    </inertial>
    <visual>
      <origin rpy="0 0 0" xyz="0 0 0"/>
      <geometry>
        <mesh filename="package://scotty_description/meshes/knee_RL_link.STL"/>
      </geometry>
      <material name="">
        <color rgba="0.89804 0.91765 0.92941 1"/>
      </material>
    </visual>
    <collision>
      <origin rpy="0 0 0" xyz="0 0 0"/>
      <geometry>
        <mesh filename="package://scotty_description/meshes/knee_RL_link.STL"/>
      </geometry>
    </collision>
  </link>
  <joint name="knee_RL_joint" type="revolute">
    <origin rpy="0 0 0" xyz="0 0.087405 -0.3"/>
    <parent link="hip_RL_link"/>
    <child link="knee_RL_link"/>
    <axis xyz="0 1 0"/>
    <limit effort="50" lower="-2.5" upper="0" velocity="3"/>
  </joint>
  <link name="foot_RL_link">
    <inertial>
      <origin rpy="0 0 0" xyz="0 0 0"/>
      <mass value="0.02"/>
      <inertia ixx="0" ixy="0" ixz="0" iyy="0" iyz="0" izz="0"/>
    </inertial>
    <visual>
      <origin rpy="0 0 0" xyz="0 0 0"/>
      <geometry>
        <mesh filename="package://scotty_description/meshes/foot_RL_link.STL"/>
      </geometry>
      <material name="">
        <color rgba="0.29804 0.29804 0.29804 1"/>
      </material>
    </visual>
    <collision>
      <origin rpy="0 0 0" xyz="0 0 0"/>
      <geometry>
        <mesh filename="package://scotty_description/meshes/foot_RL_link.STL"/>
      </geometry>
    </collision>
  </link>
  <joint name="foot_RL_joint" type="fixed">
    <origin rpy="0 0 0" xyz="0.0175 0.004395 -0.3"/>
    <parent link="knee_RL_link"/>
    <child link="foot_RL_link"/>
    <axis xyz="0 0 0"/>
  </joint>
  <!-- Define base fixed joint -->
  <link name="world"/>
  <joint name="world_to_base" type="fixed">
    <parent link="world"/>
    <child link="base_link"/>
    <origin rpy="0 0 0" xyz="0 0 0"/>
  </joint>
  <!-- IMU Link -->
  <link name="imu_link">
    <inertial>
      <mass value="0.001"/>
      <origin rpy="0 0 0" xyz="0 0 0"/>
      <inertia ixx="1e-09" ixy="0.0" ixz="0.0" iyy="1e-09" iyz="0.0" izz="1e-09"/>
    </inertial>
  </link>
  <!-- IMU Joint -->
  <joint name="imu_joint" type="fixed">
    <parent link="base_link"/>
    <child link="imu_link"/>
  </joint>
  <!-- Gazebo Plugin for IMU -->
  <gazebo>
    <plugin filename="libhector_gazebo_ros_imu.so" name="imu_controller">
      <updateRate>50.0</updateRate>
      <bodyName>imu_link</bodyName>
      <topicName>imu/data</topicName>
      <accelDrift>0.005 0.005 0.005</accelDrift>
      <accelGaussianNoise>0.005 0.005 0.005</accelGaussianNoise>
      <rateDrift>0.005 0.005 0.005 </rateDrift>
      <rateGaussianNoise>0.005 0.005 0.005 </rateGaussianNoise>
      <headingDrift>0.005</headingDrift>
      <headingGaussianNoise>0.005</headingGaussianNoise>
    </plugin>
  </gazebo>
  <!-- ros_control plugin -->
  <gazebo>
    <plugin filename="libgazebo_ros_p3d.so" name="p3d_base_controller">
      <alwaysOn>true</alwaysOn>
      <updateRate>10.0</updateRate>
      <bodyName>base_link</bodyName>
      <topicName>odom/ground_truth</topicName>
      <gaussianNoise>0.01</gaussianNoise>
      <frameName>world</frameName>
      <xyzOffsets>0 0 0</xyzOffsets>
      <rpyOffsets>0 0 0</rpyOffsets>
    </plugin>
  </gazebo>
  <gazebo>
    <plugin filename="libgazebo_ros_control.so" name="gazebo_ros_control">
      <legacyModeNS>true</legacyModeNS>
    </plugin>
  </gazebo>
  <!-- Transmissions for Front Right (FR) -->
  <transmission name="abad_FR_joint_trans">
    <type>transmission_interface/SimpleTransmission</type>
    <joint name="abad_FR_joint">
      <hardwareInterface>hardware_interface/EffortJointInterface</hardwareInterface>
    </joint>
    <actuator name="abad_FR_motor">
      <hardwareInterface>hardware_interface/EffortJointInterface</hardwareInterface>
      <mechanicalReduction>1</mechanicalReduction>
    </actuator>
  </transmission>
  <transmission name="hip_FR_joint_trans">
    <type>transmission_interface/SimpleTransmission</type>
    <joint name="hip_FR_joint">
      <hardwareInterface>hardware_interface/EffortJointInterface</hardwareInterface>
    </joint>
    <actuator name="hip_FR_motor">
      <hardwareInterface>hardware_interface/EffortJointInterface</hardwareInterface>
      <mechanicalReduction>1</mechanicalReduction>
    </actuator>
  </transmission>
  <transmission name="knee_FR_joint_trans">
    <type>transmission_interface/SimpleTransmission</type>
    <joint name="knee_FR_joint">
      <hardwareInterface>hardware_interface/EffortJointInterface</hardwareInterface>
    </joint>
    <actuator name="knee_FR_motor">
      <hardwareInterface>hardware_interface/EffortJointInterface</hardwareInterface>
      <mechanicalReduction>1</mechanicalReduction>
    </actuator>
  </transmission>
  <!-- Transmissions for Front Left (FL) -->
  <transmission name="abad_FL_joint_trans">
    <type>transmission_interface/SimpleTransmission</type>
    <joint name="abad_FL_joint">
      <hardwareInterface>hardware_interface/EffortJointInterface</hardwareInterface>
    </joint>
    <actuator name="abad_FL_motor">
      <hardwareInterface>hardware_interface/EffortJointInterface</hardwareInterface>
      <mechanicalReduction>1</mechanicalReduction>
    </actuator>
  </transmission>
  <transmission name="hip_FL_joint_trans">
    <type>transmission_interface/SimpleTransmission</type>
    <joint name="hip_FL_joint">
      <hardwareInterface>hardware_interface/EffortJointInterface</hardwareInterface>
    </joint>
    <actuator name="hip_FL_motor">
      <hardwareInterface>hardware_interface/EffortJointInterface</hardwareInterface>
      <mechanicalReduction>1</mechanicalReduction>
    </actuator>
  </transmission>
  <transmission name="knee_FL_joint_trans">
    <type>transmission_interface/SimpleTransmission</type>
    <joint name="knee_FL_joint">
      <hardwareInterface>hardware_interface/EffortJointInterface</hardwareInterface>
    </joint>
    <actuator name="knee_FL_motor">
      <hardwareInterface>hardware_interface/EffortJointInterface</hardwareInterface>
      <mechanicalReduction>1</mechanicalReduction>
    </actuator>
  </transmission>
  <!-- Transmissions for Rear Right (RR) -->
  <transmission name="abad_RR_joint_trans">
    <type>transmission_interface/SimpleTransmission</type>
    <joint name="abad_RR_joint">
      <hardwareInterface>hardware_interface/EffortJointInterface</hardwareInterface>
    </joint>
    <actuator name="abad_RR_motor">
      <hardwareInterface>hardware_interface/EffortJointInterface</hardwareInterface>
      <mechanicalReduction>1</mechanicalReduction>
    </actuator>
  </transmission>
  <transmission name="hip_RR_joint_trans">
    <type>transmission_interface/SimpleTransmission</type>
    <joint name="hip_RR_joint">
      <hardwareInterface>hardware_interface/EffortJointInterface</hardwareInterface>
    </joint>
    <actuator name="hip_RR_motor">
      <hardwareInterface>hardware_interface/EffortJointInterface</hardwareInterface>
      <mechanicalReduction>1</mechanicalReduction>
    </actuator>
  </transmission>
  <transmission name="knee_RR_joint_trans">
    <type>transmission_interface/SimpleTransmission</type>
    <joint name="knee_RR_joint">
      <hardwareInterface>hardware_interface/EffortJointInterface</hardwareInterface>
    </joint>
    <actuator name="knee_RR_motor">
      <hardwareInterface>hardware_interface/EffortJointInterface</hardwareInterface>
      <mechanicalReduction>1</mechanicalReduction>
    </actuator>
  </transmission>
  <!-- Transmissions for Rear Left (RL) -->
  <transmission name="abad_RL_joint_trans">
    <type>transmission_interface/SimpleTransmission</type>
    <joint name="abad_RL_joint">
      <hardwareInterface>hardware_interface/EffortJointInterface</hardwareInterface>
    </joint>
    <actuator name="abad_RL_motor">
      <hardwareInterface>hardware_interface/EffortJointInterface</hardwareInterface>
      <mechanicalReduction>1</mechanicalReduction>
    </actuator>
  </transmission>
  <transmission name="hip_RL_joint_trans">
    <type>transmission_interface/SimpleTransmission</type>
    <joint name="hip_RL_joint">
      <hardwareInterface>hardware_interface/EffortJointInterface</hardwareInterface>
    </joint>
    <actuator name="hip_RL_motor">
      <hardwareInterface>hardware_interface/EffortJointInterface</hardwareInterface>
      <mechanicalReduction>1</mechanicalReduction>
    </actuator>
  </transmission>
  <transmission name="knee_RL_joint_trans">
    <type>transmission_interface/SimpleTransmission</type>
    <joint name="knee_RL_joint">
      <hardwareInterface>hardware_interface/EffortJointInterface</hardwareInterface>
    </joint>
    <actuator name="knee_RL_motor">
      <hardwareInterface>hardware_interface/EffortJointInterface</hardwareInterface>
      <mechanicalReduction>1</mechanicalReduction>
    </actuator>
  </transmission>
</robot>

