<?xml version="1.0" ?>
<!-- =================================================================================== -->
<!-- |    This document was autogenerated by xacro from scotty_final.urdf.xacro        | -->
<!-- |    EDITING THIS FILE BY HAND IS NOT RECOMMENDED                                 | -->
<!-- =================================================================================== -->
<robot name="scotty_robot" xmlns:xacro="http://ros.org/wiki/xacro">
  <link name="base_link">
    <inertial>
      <origin rpy="0 0 0" xyz="0.0314483846788916 -6.55218724121662E-05 0.0248392392910642"/>
      <mass value="3.85607896940888"/>
      <inertia ixx="0.0138867117837616" ixy="-2.90278660215377E-08" ixz="-2.58875884175343E-06" iyy="0.0172236043367669" iyz="-8.35666921709627E-09" izz="0.0236113226656801"/>
    </inertial>
    <visual>
      <origin rpy="0 0 0" xyz="0 0 0"/>
      <geometry>
        <mesh filename="package://scotty_description/meshes/base_link.STL"/>
      </geometry>
      <material name="">
        <color rgba="0.898039215686275 0.917647058823529 0.929411764705882 1"/>
      </material>
    </visual>
    <collision>
      <origin rpy="0 0 0" xyz="0 0 0"/>
      <geometry>
        <mesh filename="package://scotty_description/meshes/base_link.STL"/>
      </geometry>
    </collision>
  </link>
  <link name="abad_FR_link">
    <inertial>
      <origin rpy="0 0 0" xyz="0.0589056087369735 -0.000893751193795894 1.31027647427551E-05"/>
      <mass value="0.415086541078643"/>
      <inertia ixx="0.000347299510368134" ixy="-9.24015776265909E-07" ixz="-1.74428373569239E-07" iyy="0.000490589240902945" iyz="1.49882254445195E-08" izz="0.000292030535672053"/>
    </inertial>
    <visual>
      <origin rpy="0 0 0" xyz="0 0 0"/>
      <geometry>
        <mesh filename="package://scotty_description/meshes/abad_FR_link.STL"/>
      </geometry>
      <material name="">
        <color rgba="0.298039215686275 0.298039215686275 0.298039215686275 1"/>
      </material>
    </visual>
    <collision>
      <origin rpy="0 0 0" xyz="0 0 0"/>
      <geometry>
        <mesh filename="package://scotty_description/meshes/abad_FR_link.STL"/>
      </geometry>
    </collision>
  </link>
  <joint name="abad_FR_joint" type="revolute">
    <origin rpy="0 0 0" xyz="0.2485 -0.065 0.025"/>
    <parent link="base_link"/>
    <child link="abad_FR_link"/>
    <axis xyz="1 0 0"/>
    <limit effort="25" lower="-0.65" upper="0.65" velocity="3"/>
  </joint>
  <link name="hip_FR_link">
    <inertial>
      <origin rpy="0 0 0" xyz="-0.000456154664474892 -0.0698896205031284 -0.0639468843908812"/>
      <mass value="1.05302815476358"/>
      <inertia ixx="0.00387984063210811" ixy="-1.21559516987344E-06" ixz="-5.21353454625218E-06" iyy="0.00443119515122231" iyz="-1.22999714185811E-06" izz="0.000775321583761757"/>
    </inertial>
    <visual>
      <origin rpy="0 0 0" xyz="0 0 0"/>
      <geometry>
        <mesh filename="package://scotty_description/meshes/hip_FR_link.STL"/>
      </geometry>
      <material name="">
        <color rgba="0.298039215686275 0.298039215686275 0.298039215686275 1"/>
      </material>
    </visual>
    <collision>
      <origin rpy="0 0 0" xyz="0 0 0"/>
      <geometry>
        <mesh filename="package://scotty_description/meshes/hip_FR_link.STL"/>
      </geometry>
    </collision>
  </link>
  <joint name="hip_FR_joint" type="revolute">
    <origin rpy="0 0 0" xyz="0.065 -0.03 0"/>
    <parent link="abad_FR_link"/>
    <child link="hip_FR_link"/>
    <axis xyz="0 1 0"/>
    <limit effort="50" lower="-1.25" upper="1.8" velocity="3"/>
  </joint>
  <link name="knee_FR_link">
    <inertial>
      <origin rpy="0 0 0" xyz="0.0164835065596182 -0.0013627043911752 -0.153846648019093"/>
      <mass value="0.367874494498672"/>
      <inertia ixx="0.00262374429195262" ixy="-1.08195990780416E-09" ixz="0.000246070252835904" iyy="0.00268159880702631" iyz="-4.03703953581917E-09" izz="7.25195050257749E-05"/>
    </inertial>
    <visual>
      <origin rpy="0 0 0" xyz="0 0 0"/>
      <geometry>
        <mesh filename="package://scotty_description/meshes/knee_FR_link.STL"/>
      </geometry>
      <material name="">
        <color rgba="0.898039215686275 0.917647058823529 0.929411764705882 1"/>
      </material>
    </visual>
    <collision>
      <origin rpy="0 0 0" xyz="0 0 0"/>
      <geometry>
        <mesh filename="package://scotty_description/meshes/knee_FR_link.STL"/>
      </geometry>
    </collision>
  </link>
  <joint name="knee_FR_joint" type="revolute">
    <origin rpy="0 0 0" xyz="0 -0.087405 -0.3"/>
    <parent link="hip_FR_link"/>
    <child link="knee_FR_link"/>
    <axis xyz="0 1 0"/>
    <limit effort="50" lower="-2.5" upper="0" velocity="3"/>
  </joint>
  <link name="abad_FL_link">
    <inertial>
      <origin rpy="0 0 0" xyz="0.05890560854102 0.000893751392354647 -1.31070407718629E-05"/>
      <mass value="0.415086538333225"/>
      <inertia ixx="0.000347299510088798" ixy="9.24015742187451E-07" ixz="1.74423512564253E-07" iyy="0.000490589238662559" iyz="1.49881716375163E-08" izz="0.000292030533706022"/>
    </inertial>
    <visual>
      <origin rpy="0 0 0" xyz="0 0 0"/>
      <geometry>
        <mesh filename="package://scotty_description/meshes/abad_FL_link.STL"/>
      </geometry>
      <material name="">
        <color rgba="0.752941176470588 0.752941176470588 0.752941176470588 1"/>
      </material>
    </visual>
    <collision>
      <origin rpy="0 0 0" xyz="0 0 0"/>
      <geometry>
        <mesh filename="package://scotty_description/meshes/abad_FL_link.STL"/>
      </geometry>
    </collision>
  </link>
  <joint name="abad_FL_joint" type="revolute">
    <origin rpy="0 0 0" xyz="0.2485 0.065 0.025"/>
    <parent link="base_link"/>
    <child link="abad_FL_link"/>
    <axis xyz="1 0 0"/>
    <limit effort="25" lower="-0.65" upper="0.65" velocity="3"/>
  </joint>
  <link name="hip_FL_link">
    <inertial>
      <origin rpy="0 0 0" xyz="-0.000456157514379579 0.0698896203636033 -0.064200499986891"/>
      <mass value="1.05302815750899"/>
      <inertia ixx="0.00387984063279086" ixy="1.21560012449625E-06" ixz="5.21342074080021E-06" iyy="0.0044311951534627" iyz="1.86326216107651E-06" izz="0.000775321585324375"/>
    </inertial>
    <visual>
      <origin rpy="0 0 0" xyz="0 0 0"/>
      <geometry>
        <mesh filename="package://scotty_description/meshes/hip_FL_link.STL"/>
      </geometry>
      <material name="">
        <color rgba="0.298039215686275 0.298039215686275 0.298039215686275 1"/>
      </material>
    </visual>
    <collision>
      <origin rpy="0 0 0" xyz="0 0 0"/>
      <geometry>
        <mesh filename="package://scotty_description/meshes/hip_FL_link.STL"/>
      </geometry>
    </collision>
  </link>
  <joint name="hip_FL_joint" type="revolute">
    <origin rpy="0 0 0" xyz="0.065 0.03 0"/>
    <parent link="abad_FL_link"/>
    <child link="hip_FL_link"/>
    <axis xyz="0 1 0"/>
    <limit effort="50" lower="-1.25" upper="1.8" velocity="3"/>
  </joint>
  <link name="knee_FL_link">
    <inertial>
      <origin rpy="0 0 0" xyz="0.0164835065607707 0.00136979747534019 -0.153846648020307"/>
      <mass value="0.367874494498672"/>
      <inertia ixx="0.00262374429195376" ixy="-1.08195805869797E-09" ixz="0.00024607025283367" iyy="0.00268159880702632" iyz="-4.03703764929651E-09" izz="7.2519505024648E-05"/>
    </inertial>
    <visual>
      <origin rpy="0 0 0" xyz="0 0 0"/>
      <geometry>
        <mesh filename="package://scotty_description/meshes/knee_FL_link.STL"/>
      </geometry>
      <material name="">
        <color rgba="0.898039215686275 0.917647058823529 0.929411764705882 1"/>
      </material>
    </visual>
    <collision>
      <origin rpy="0 0 0" xyz="0 0 0"/>
      <geometry>
        <mesh filename="package://scotty_description/meshes/knee_FL_link.STL"/>
      </geometry>
    </collision>
  </link>
  <joint name="knee_FL_joint" type="revolute">
    <origin rpy="0 0 0" xyz="0 0.087405 -0.3"/>
    <parent link="hip_FL_link"/>
    <child link="knee_FL_link"/>
    <axis xyz="0 1 0"/>
    <limit effort="50" lower="-2.5" upper="0" velocity="3"/>
  </joint>
  <link name="abad_RR_link">
    <inertial>
      <origin rpy="0 0 0" xyz="-0.0589056087364921 -0.000893751193796241 -1.31049387939929E-05"/>
      <mass value="0.415086541078617"/>
      <inertia ixx="0.000347299510381008" ixy="9.24015776818508E-07" ixz="-1.74426333713997E-07" iyy="0.000490589240902941" iyz="-1.49881913351498E-08" izz="0.000292030535659179"/>
    </inertial>
    <visual>
      <origin rpy="0 0 0" xyz="0 0 0"/>
      <geometry>
        <mesh filename="package://scotty_description/meshes/abad_RR_link.STL"/>
      </geometry>
      <material name="">
        <color rgba="0.752941176470588 0.752941176470588 0.752941176470588 1"/>
      </material>
    </visual>
    <collision>
      <origin rpy="0 0 0" xyz="0 0 0"/>
      <geometry>
        <mesh filename="package://scotty_description/meshes/abad_RR_link.STL"/>
      </geometry>
    </collision>
  </link>
  <joint name="abad_RR_joint" type="revolute">
    <origin rpy="0 0 0" xyz="-0.2485 -0.065 0.025"/>
    <parent link="base_link"/>
    <child link="abad_RR_link"/>
    <axis xyz="1 0 0"/>
    <limit effort="25" lower="-0.65" upper="0.65" velocity="3"/>
  </joint>
  <link name="hip_RR_link">
    <inertial>
      <origin rpy="0 0 0" xyz="0.000337894221847379 -0.0698896203602006 -0.0637420543515784"/>
      <mass value="1.05302815757229"/>
      <inertia ixx="0.00387138194603533" ixy="8.8201303044837E-07" ixz="1.00971190970239E-05" iyy="0.0044311951535269" iyz="-6.52207544665015E-07" izz="0.000783780272143608"/>
    </inertial>
    <visual>
      <origin rpy="0 0 0" xyz="0 0 0"/>
      <geometry>
        <mesh filename="package://scotty_description/meshes/hip_RR_link.STL"/>
      </geometry>
      <material name="">
        <color rgba="0.752941176470588 0.752941176470588 0.752941176470588 1"/>
      </material>
    </visual>
    <collision>
      <origin rpy="0 0 0" xyz="0 0 0"/>
      <geometry>
        <mesh filename="package://scotty_description/meshes/hip_RR_link.STL"/>
      </geometry>
    </collision>
  </link>
  <joint name="hip_RR_joint" type="revolute">
    <origin rpy="0 0 0" xyz="-0.065 -0.03 0"/>
    <parent link="abad_RR_link"/>
    <child link="hip_RR_link"/>
    <axis xyz="0 1 0"/>
    <limit effort="50" lower="-1.25" upper="1.8" velocity="3"/>
  </joint>
  <link name="knee_RR_link">
    <inertial>
      <origin rpy="0 0 0" xyz="0.0164835008826912 -0.00136270439117511 -0.153846648628661"/>
      <mass value="0.367874494498672"/>
      <inertia ixx="0.00262374431011734" ixy="-1.08195820749471E-09" ixz="0.000246070158674825" iyy="0.00268159880702633" iyz="-4.03703761210357E-09" izz="7.25194868610689E-05"/>
    </inertial>
    <visual>
      <origin rpy="0 0 0" xyz="0 0 0"/>
      <geometry>
        <mesh filename="package://scotty_description/meshes/knee_RR_link.STL"/>
      </geometry>
      <material name="">
        <color rgba="0.898039215686275 0.917647058823529 0.929411764705882 1"/>
      </material>
    </visual>
    <collision>
      <origin rpy="0 0 0" xyz="0 0 0"/>
      <geometry>
        <mesh filename="package://scotty_description/meshes/knee_RR_link.STL"/>
      </geometry>
    </collision>
  </link>
  <joint name="knee_RR_joint" type="revolute">
    <origin rpy="0 0 0" xyz="0 -0.087405 -0.3"/>
    <parent link="hip_RR_link"/>
    <child link="knee_RR_link"/>
    <axis xyz="0 1 0"/>
    <limit effort="50" lower="-2.5" upper="0" velocity="3"/>
  </joint>
  <link name="abad_RL_link">
    <inertial>
      <origin rpy="0 0 0" xyz="-0.0589056085415005 0.000893751392353648 1.31048667230375E-05"/>
      <mass value="0.415086538333242"/>
      <inertia ixx="0.000347299510075886" ixy="-9.24015741630928E-07" ixz="1.74425552403158E-07" iyy="0.00049058923866253" iyz="-1.49882057398317E-08" izz="0.000292030533718918"/>
    </inertial>
    <visual>
      <origin rpy="0 0 0" xyz="0 0 0"/>
      <geometry>
        <mesh filename="package://scotty_description/meshes/abad_RL_link.STL"/>
      </geometry>
      <material name="">
        <color rgba="0.752941176470588 0.752941176470588 0.752941176470588 1"/>
      </material>
    </visual>
    <collision>
      <origin rpy="0 0 0" xyz="0 0 0"/>
      <geometry>
        <mesh filename="package://scotty_description/meshes/abad_RL_link.STL"/>
      </geometry>
    </collision>
  </link>
  <joint name="abad_RL_joint" type="revolute">
    <origin rpy="0 0 0" xyz="-0.2485 0.065 0.025"/>
    <parent link="base_link"/>
    <child link="abad_RL_link"/>
    <axis xyz="1 0 0"/>
    <limit effort="25" lower="-0.65" upper="0.65" velocity="3"/>
  </joint>
  <link name="hip_RL_link">
    <inertial>
      <origin rpy="0 0 0" xyz="0.000456154664752351 0.0698896205031295 -0.0639468843923549"/>
      <mass value="1.05302815476357"/>
      <inertia ixx="0.00387984063210762" ixy="-1.2155951714069E-06" ixz="5.21353454653872E-06" iyy="0.00443119515122222" iyz="1.22999715081411E-06" izz="0.000775321583762167"/>
    </inertial>
    <visual>
      <origin rpy="0 0 0" xyz="0 0 0"/>
      <geometry>
        <mesh filename="package://scotty_description/meshes/hip_RL_link.STL"/>
      </geometry>
      <material name="">
        <color rgba="0.298039215686275 0.298039215686275 0.298039215686275 1"/>
      </material>
    </visual>
    <collision>
      <origin rpy="0 0 0" xyz="0 0 0"/>
      <geometry>
        <mesh filename="package://scotty_description/meshes/hip_RL_link.STL"/>
      </geometry>
    </collision>
  </link>
  <joint name="hip_RL_joint" type="revolute">
    <origin rpy="0 0 0" xyz="-0.065 0.03 0"/>
    <parent link="abad_RL_link"/>
    <child link="hip_RL_link"/>
    <axis xyz="0 1 0"/>
    <limit effort="50" lower="-1.25" upper="1.8" velocity="3"/>
  </joint>
  <link name="knee_RL_link">
    <inertial>
      <origin rpy="0 0 0" xyz="0.0164835065607598 0.00142729560882487 -0.153846648020305"/>
      <mass value="0.367874494498672"/>
      <inertia ixx="0.00262374429195376" ixy="-1.08195805856593E-09" ixz="0.000246070252833701" iyy="0.00268159880702633" iyz="-4.03703765123224E-09" izz="7.25195050246535E-05"/>
    </inertial>
    <visual>
      <origin rpy="0 0 0" xyz="0 0 0"/>
      <geometry>
        <mesh filename="package://scotty_description/meshes/knee_RL_link.STL"/>
      </geometry>
      <material name="">
        <color rgba="0.898039215686275 0.917647058823529 0.929411764705882 1"/>
      </material>
    </visual>
    <collision>
      <origin rpy="0 0 0" xyz="0 0 0"/>
      <geometry>
        <mesh filename="package://scotty_description/meshes/knee_RL_link.STL"/>
      </geometry>
    </collision>
  </link>
  <joint name="knee_RL_joint" type="revolute">
    <origin rpy="0 0 0" xyz="0 0.087405 -0.3"/>
    <parent link="hip_RL_link"/>
    <child link="knee_RL_link"/>
    <axis xyz="0 1 0"/>
    <limit effort="50" lower="-2.5" upper="0" velocity="3"/>
  </joint>
  <!-- Define base fixed joint -->
  <joint name="world_to_base" type="fixed">
    <parent link="world"/>
    <child link="base_link"/>
    <origin rpy="0 0 0" xyz="0 0 0"/>
  </joint>
  <!-- IMU Link -->
  <link name="imu_link">
    <inertial>
      <mass value="0.001"/>
      <origin rpy="0 0 0" xyz="0 0 0"/>
      <inertia ixx="1e-09" ixy="0.0" ixz="0.0" iyy="1e-09" iyz="0.0" izz="1e-09"/>
    </inertial>
  </link>
  <!-- IMU Joint -->
  <joint name="imu_joint" type="fixed">
    <parent link="base_link"/>
    <child link="imu_link"/>
  </joint>
  <!-- Gazebo Plugin for IMU -->
  <gazebo>
    <plugin filename="libhector_gazebo_ros_imu.so" name="imu_controller">
      <updateRate>50.0</updateRate>
      <bodyName>imu_link</bodyName>
      <topicName>imu/data</topicName>
      <accelDrift>0.005 0.005 0.005</accelDrift>
      <accelGaussianNoise>0.005 0.005 0.005</accelGaussianNoise>
      <rateDrift>0.005 0.005 0.005 </rateDrift>
      <rateGaussianNoise>0.005 0.005 0.005 </rateGaussianNoise>
      <headingDrift>0.005</headingDrift>
      <headingGaussianNoise>0.005</headingGaussianNoise>
    </plugin>
  </gazebo>
  <!-- Front Right (FR) Foot -->
  <link name="foot_FR_link"/>
  <joint name="foot_FR_joint" type="fixed">
    <parent link="knee_FR_link"/>
    <child link="foot_FR_link"/>
    <origin rpy="0 0 0" xyz="0 0 -0.32"/>
  </joint>
  <!-- Front Left (FL) Foot -->
  <link name="foot_FL_link"/>
  <joint name="foot_FL_joint" type="fixed">
    <parent link="knee_FL_link"/>
    <child link="foot_FL_link"/>
    <origin rpy="0 0 0" xyz="0 0 -0.32"/>
  </joint>
  <!-- Rear Right (RR) Foot -->
  <link name="foot_RR_link"/>
  <joint name="foot_RR_joint" type="fixed">
    <parent link="knee_RR_link"/>
    <child link="foot_RR_link"/>
    <origin rpy="0 0 0" xyz="0 0 -0.32"/>
  </joint>
  <!-- Rear Left (RL) Foot -->
  <link name="foot_RL_link"/>
  <joint name="foot_RL_joint" type="fixed">
    <parent link="knee_RL_link"/>
    <child link="foot_RL_link"/>
    <origin rpy="0 0 0" xyz="0 0 -0.32"/>
  </joint>
</robot>

