<?xml version="1.0" encoding="utf-8"?>
<!-- This URDF was automatically created by SolidWorks to URDF Exporter! Originally created by Stephen Brawner (brawner@gmail.com) 
     Commit Version: 1.6.0-4-g7f85cfe  Build Version: 1.6.7995.38578
     For more information, please see http://wiki.ros.org/sw_urdf_exporter -->
<robot
  name="scotty_description">
  <link
    name="base_link">
    <inertial>
      <origin
        xyz="0.0314483846788916 -6.55218724121617E-05 0.0248392392910642"
        rpy="0 0 0" />
      <mass
        value="3.85607896940888" />
      <inertia
        ixx="0.0138867117837616"
        ixy="-2.90278660214883E-08"
        ixz="-2.58875884175338E-06"
        iyy="0.0172236043367669"
        iyz="-8.3566692172544E-09"
        izz="0.0236113226656801" />
    </inertial>
    <visual>
      <origin
        xyz="0 0 0"
        rpy="0 0 0" />
      <geometry>
        <mesh
          filename="package://scotty_description/meshes/base_link.STL" />
      </geometry>
      <material
        name="">
        <color
          rgba="0.898039215686275 0.917647058823529 0.929411764705882 1" />
      </material>
    </visual>
    <collision>
      <origin
        xyz="0 0 0"
        rpy="0 0 0" />
      <geometry>
        <mesh
          filename="package://scotty_description/meshes/base_link.STL" />
      </geometry>
    </collision>
  </link>
  <link
    name="abad_FR_link">
    <inertial>
      <origin
        xyz="0.0589056087369735 -0.000893751193795922 1.3102764742755E-05"
        rpy="0 0 0" />
      <mass
        value="0.415086541078643" />
      <inertia
        ixx="0.000347299510368134"
        ixy="-9.24015776265909E-07"
        ixz="-1.74428373569239E-07"
        iyy="0.000490589240902945"
        iyz="1.49882254445193E-08"
        izz="0.000292030535672053" />
    </inertial>
    <visual>
      <origin
        xyz="0 0 0"
        rpy="0 0 0" />
      <geometry>
        <mesh
          filename="package://scotty_description/meshes/abad_FR_link.STL" />
      </geometry>
      <material
        name="">
        <color
          rgba="0.298039215686275 0.298039215686275 0.298039215686275 1" />
      </material>
    </visual>
    <collision>
      <origin
        xyz="0 0 0"
        rpy="0 0 0" />
      <geometry>
        <mesh
          filename="package://scotty_description/meshes/abad_FR_link.STL" />
      </geometry>
    </collision>
  </link>
  <joint
    name="abad_FR_joint"
    type="revolute">
    <origin
      xyz="0.248499999209484 -0.0650000004417044 0.0250000036169163"
      rpy="0 0 0" />
    <parent
      link="base_link" />
    <child
      link="abad_FR_link" />
    <axis
      xyz="-0.999999999999999 0 0" />
    <limit
      lower="-0.65"
      upper="0.65"
      effort="25"
      velocity="3" />
  </joint>
  <link
    name="hip_FR_link">
    <inertial>
      <origin
        xyz="-0.000456154664474906 -0.0698896205031284 -0.0639468843908812"
        rpy="0 0 0" />
      <mass
        value="1.05302815476358" />
      <inertia
        ixx="0.00387984063210811"
        ixy="-1.21559516987344E-06"
        ixz="-5.21353454625216E-06"
        iyy="0.00443119515122231"
        iyz="-1.22999714185811E-06"
        izz="0.000775321583761757" />
    </inertial>
    <visual>
      <origin
        xyz="0 0 0"
        rpy="0 0 0" />
      <geometry>
        <mesh
          filename="package://scotty_description/meshes/hip_FR_link.STL" />
      </geometry>
      <material
        name="">
        <color
          rgba="0.298039215686275 0.298039215686275 0.298039215686275 1" />
      </material>
    </visual>
    <collision>
      <origin
        xyz="0 0 0"
        rpy="0 0 0" />
      <geometry>
        <mesh
          filename="package://scotty_description/meshes/hip_FR_link.STL" />
      </geometry>
    </collision>
  </link>
  <joint
    name="hip_FR_joint"
    type="revolute">
    <origin
      xyz="0.0649999999999999 -0.03 0"
      rpy="0 0 0" />
    <parent
      link="abad_FR_link" />
    <child
      link="hip_FR_link" />
    <axis
      xyz="0 1 0" />
    <limit
      lower="-1.25"
      upper="1.8"
      effort="50"
      velocity="3" />
  </joint>
  <link
    name="knee_FR_link">
    <inertial>
      <origin
        xyz="0.0164835065596182 -0.00136270439117517 -0.153846648019093"
        rpy="0 0 0" />
      <mass
        value="0.367874494498672" />
      <inertia
        ixx="0.00262374429195262"
        ixy="-1.08195990780376E-09"
        ixz="0.000246070252835904"
        iyy="0.00268159880702631"
        iyz="-4.03703953581241E-09"
        izz="7.25195050257749E-05" />
    </inertial>
    <visual>
      <origin
        xyz="0 0 0"
        rpy="0 0 0" />
      <geometry>
        <mesh
          filename="package://scotty_description/meshes/knee_FR_link.STL" />
      </geometry>
      <material
        name="">
        <color
          rgba="0.898039215686275 0.917647058823529 0.929411764705882 1" />
      </material>
    </visual>
    <collision>
      <origin
        xyz="0 0 0"
        rpy="0 0 0" />
      <geometry>
        <mesh
          filename="package://scotty_description/meshes/knee_FR_link.STL" />
      </geometry>
    </collision>
  </link>
  <joint
    name="knee_FR_joint"
    type="revolute">
    <origin
      xyz="0 -0.087404999999999 -0.3"
      rpy="0 0 0" />
    <parent
      link="hip_FR_link" />
    <child
      link="knee_FR_link" />
    <axis
      xyz="0 1 0" />
    <limit
      lower="-2.5"
      upper="0"
      effort="50"
      velocity="3" />
  </joint>
  <link
    name="abad_FL_link">
    <inertial>
      <origin
        xyz="0.05890560854102 0.000893751392354647 -1.31070407718628E-05"
        rpy="0 0 0" />
      <mass
        value="0.415086538333225" />
      <inertia
        ixx="0.000347299510088798"
        ixy="9.24015742187453E-07"
        ixz="1.74423512564253E-07"
        iyy="0.000490589238662559"
        iyz="1.49881716375157E-08"
        izz="0.000292030533706022" />
    </inertial>
    <visual>
      <origin
        xyz="0 0 0"
        rpy="0 0 0" />
      <geometry>
        <mesh
          filename="package://scotty_description/meshes/abad_FL_link.STL" />
      </geometry>
      <material
        name="">
        <color
          rgba="0.752941176470588 0.752941176470588 0.752941176470588 1" />
      </material>
    </visual>
    <collision>
      <origin
        xyz="0 0 0"
        rpy="0 0 0" />
      <geometry>
        <mesh
          filename="package://scotty_description/meshes/abad_FL_link.STL" />
      </geometry>
    </collision>
  </link>
  <joint
    name="abad_FL_joint"
    type="revolute">
    <origin
      xyz="0.248499999209484 0.0649999995582956 0.0250000036169165"
      rpy="0 0 0" />
    <parent
      link="base_link" />
    <child
      link="abad_FL_link" />
    <axis
      xyz="-0.999999999999999 0 0" />
    <limit
      lower="-0.65"
      upper="0.65"
      effort="25"
      velocity="3" />
  </joint>
  <link
    name="hip_FL_link">
    <inertial>
      <origin
        xyz="-0.000456157514379593 0.0698896203636033 -0.064200499986891"
        rpy="0 0 0" />
      <mass
        value="1.05302815750899" />
      <inertia
        ixx="0.00387984063279086"
        ixy="1.21560012449625E-06"
        ixz="5.21342074080019E-06"
        iyy="0.0044311951534627"
        iyz="1.8632621610765E-06"
        izz="0.000775321585324375" />
    </inertial>
    <visual>
      <origin
        xyz="0 0 0"
        rpy="0 0 0" />
      <geometry>
        <mesh
          filename="package://scotty_description/meshes/hip_FL_link.STL" />
      </geometry>
      <material
        name="">
        <color
          rgba="0.298039215686275 0.298039215686275 0.298039215686275 1" />
      </material>
    </visual>
    <collision>
      <origin
        xyz="0 0 0"
        rpy="0 0 0" />
      <geometry>
        <mesh
          filename="package://scotty_description/meshes/hip_FL_link.STL" />
      </geometry>
    </collision>
  </link>
  <joint
    name="hip_FL_joint"
    type="revolute">
    <origin
      xyz="0.0649999999999999 0.0300000000000002 0"
      rpy="0 0 0" />
    <parent
      link="abad_FL_link" />
    <child
      link="hip_FL_link" />
    <axis
      xyz="0 -1 0" />
    <limit
      lower="-1.25"
      upper="1.8"
      effort="50"
      velocity="3" />
  </joint>
  <link
    name="knee_FL_link">
    <inertial>
      <origin
        xyz="0.0164835065607707 0.00136979747534019 -0.153846648020307"
        rpy="0 0 0" />
      <mass
        value="0.367874494498672" />
      <inertia
        ixx="0.00262374429195376"
        ixy="-1.08195805869924E-09"
        ixz="0.00024607025283367"
        iyy="0.00268159880702632"
        iyz="-4.03703764930328E-09"
        izz="7.2519505024648E-05" />
    </inertial>
    <visual>
      <origin
        xyz="0 0 0"
        rpy="0 0 0" />
      <geometry>
        <mesh
          filename="package://scotty_description/meshes/knee_FL_link.STL" />
      </geometry>
      <material
        name="">
        <color
          rgba="0.898039215686275 0.917647058823529 0.929411764705882 1" />
      </material>
    </visual>
    <collision>
      <origin
        xyz="0 0 0"
        rpy="0 0 0" />
      <geometry>
        <mesh
          filename="package://scotty_description/meshes/knee_FL_link.STL" />
      </geometry>
    </collision>
  </link>
  <joint
    name="knee_FL_joint"
    type="revolute">
    <origin
      xyz="0 0.087405 -0.3"
      rpy="0 0 0" />
    <parent
      link="hip_FL_link" />
    <child
      link="knee_FL_link" />
    <axis
      xyz="0 -1 0" />
    <limit
      lower="-2.5"
      upper="0"
      effort="50"
      velocity="3" />
  </joint>
  <link
    name="abad_RR_link">
    <inertial>
      <origin
        xyz="-0.0589056087364921 -0.000893751193796241 -1.31049387939931E-05"
        rpy="0 0 0" />
      <mass
        value="0.415086541078617" />
      <inertia
        ixx="0.000347299510381008"
        ixy="9.24015776818509E-07"
        ixz="-1.74426333713996E-07"
        iyy="0.000490589240902941"
        iyz="-1.49881913351496E-08"
        izz="0.000292030535659179" />
    </inertial>
    <visual>
      <origin
        xyz="0 0 0"
        rpy="0 0 0" />
      <geometry>
        <mesh
          filename="package://scotty_description/meshes/abad_RR_link.STL" />
      </geometry>
      <material
        name="">
        <color
          rgba="0.752941176470588 0.752941176470588 0.752941176470588 1" />
      </material>
    </visual>
    <collision>
      <origin
        xyz="0 0 0"
        rpy="0 0 0" />
      <geometry>
        <mesh
          filename="package://scotty_description/meshes/abad_RR_link.STL" />
      </geometry>
    </collision>
  </link>
  <joint
    name="abad_RR_joint"
    type="revolute">
    <origin
      xyz="-0.2485 -0.065 0.025"
      rpy="0 0 0" />
    <parent
      link="base_link" />
    <child
      link="abad_RR_link" />
    <axis
      xyz="1 0 0" />
    <limit
      lower="-0.65"
      upper="0.65"
      effort="25"
      velocity="3" />
  </joint>
  <link
    name="hip_RR_link">
    <inertial>
      <origin
        xyz="0.00033789422184749 -0.0698896203602006 -0.0637420543515784"
        rpy="0 0 0" />
      <mass
        value="1.05302815757229" />
      <inertia
        ixx="0.00387138194603533"
        ixy="8.8201303044837E-07"
        ixz="1.0097119097024E-05"
        iyy="0.0044311951535269"
        iyz="-6.52207544665015E-07"
        izz="0.000783780272143608" />
    </inertial>
    <visual>
      <origin
        xyz="0 0 0"
        rpy="0 0 0" />
      <geometry>
        <mesh
          filename="package://scotty_description/meshes/hip_RR_link.STL" />
      </geometry>
      <material
        name="">
        <color
          rgba="0.752941176470588 0.752941176470588 0.752941176470588 1" />
      </material>
    </visual>
    <collision>
      <origin
        xyz="0 0 0"
        rpy="0 0 0" />
      <geometry>
        <mesh
          filename="package://scotty_description/meshes/hip_RR_link.STL" />
      </geometry>
    </collision>
  </link>
  <joint
    name="hip_RR_joint"
    type="revolute">
    <origin
      xyz="-0.0650000000000002 -0.03 0"
      rpy="0 0 0" />
    <parent
      link="abad_RR_link" />
    <child
      link="hip_RR_link" />
    <axis
      xyz="0 1 0" />
    <limit
      lower="-1.25"
      upper="1.8"
      effort="50"
      velocity="3" />
  </joint>
  <link
    name="knee_RR_link">
    <inertial>
      <origin
        xyz="0.0164835008826913 -0.00136270439117514 -0.153846648628661"
        rpy="0 0 0" />
      <mass
        value="0.367874494498673" />
      <inertia
        ixx="0.00262374431011734"
        ixy="-1.08195820749385E-09"
        ixz="0.000246070158674825"
        iyy="0.00268159880702633"
        iyz="-4.03703761211037E-09"
        izz="7.25194868610689E-05" />
    </inertial>
    <visual>
      <origin
        xyz="0 0 0"
        rpy="0 0 0" />
      <geometry>
        <mesh
          filename="package://scotty_description/meshes/knee_RR_link.STL" />
      </geometry>
      <material
        name="">
        <color
          rgba="0.898039215686275 0.917647058823529 0.929411764705882 1" />
      </material>
    </visual>
    <collision>
      <origin
        xyz="0 0 0"
        rpy="0 0 0" />
      <geometry>
        <mesh
          filename="package://scotty_description/meshes/knee_RR_link.STL" />
      </geometry>
    </collision>
  </link>
  <joint
    name="knee_RR_joint"
    type="revolute">
    <origin
      xyz="0 -0.087405 -0.3"
      rpy="0 0 0" />
    <parent
      link="hip_RR_link" />
    <child
      link="knee_RR_link" />
    <axis
      xyz="0 1 0" />
    <limit
      lower="-2.5"
      upper="0"
      effort="50"
      velocity="3" />
  </joint>
  <link
    name="abad_RL_link">
    <inertial>
      <origin
        xyz="-0.0589056085415005 0.000893751392353648 1.31048667230375E-05"
        rpy="0 0 0" />
      <mass
        value="0.415086538333242" />
      <inertia
        ixx="0.000347299510075885"
        ixy="-9.24015741630927E-07"
        ixz="1.74425552403159E-07"
        iyy="0.00049058923866253"
        iyz="-1.49882057398314E-08"
        izz="0.000292030533718918" />
    </inertial>
    <visual>
      <origin
        xyz="0 0 0"
        rpy="0 0 0" />
      <geometry>
        <mesh
          filename="package://scotty_description/meshes/abad_RL_link.STL" />
      </geometry>
      <material
        name="">
        <color
          rgba="0.752941176470588 0.752941176470588 0.752941176470588 1" />
      </material>
    </visual>
    <collision>
      <origin
        xyz="0 0 0"
        rpy="0 0 0" />
      <geometry>
        <mesh
          filename="package://scotty_description/meshes/abad_RL_link.STL" />
      </geometry>
    </collision>
  </link>
  <joint
    name="abad_RL_joint"
    type="revolute">
    <origin
      xyz="-0.248500000236906 0.0649999995582957 0.0249999944454496"
      rpy="0 0 0" />
    <parent
      link="base_link" />
    <child
      link="abad_RL_link" />
    <axis
      xyz="1 0 0" />
    <limit
      lower="-0.65"
      upper="0.65"
      effort="25"
      velocity="3" />
  </joint>
  <link
    name="hip_RL_link">
    <inertial>
      <origin
        xyz="0.000456154664752573 0.0698896205031295 -0.0639468843923549"
        rpy="0 0 0" />
      <mass
        value="1.05302815476357" />
      <inertia
        ixx="0.00387984063210762"
        ixy="-1.2155951714069E-06"
        ixz="5.21353454653872E-06"
        iyy="0.00443119515122222"
        iyz="1.2299971508141E-06"
        izz="0.000775321583762167" />
    </inertial>
    <visual>
      <origin
        xyz="0 0 0"
        rpy="0 0 0" />
      <geometry>
        <mesh
          filename="package://scotty_description/meshes/hip_RL_link.STL" />
      </geometry>
      <material
        name="">
        <color
          rgba="0.298039215686275 0.298039215686275 0.298039215686275 1" />
      </material>
    </visual>
    <collision>
      <origin
        xyz="0 0 0"
        rpy="0 0 0" />
      <geometry>
        <mesh
          filename="package://scotty_description/meshes/hip_RL_link.STL" />
      </geometry>
    </collision>
  </link>
  <joint
    name="hip_RL_joint"
    type="revolute">
    <origin
      xyz="-0.065 0.0300000000000001 0"
      rpy="0 0 0" />
    <parent
      link="abad_RL_link" />
    <child
      link="hip_RL_link" />
    <axis
      xyz="0 -1 0" />
    <limit
      lower="-1.25"
      upper="1.8"
      effort="50"
      velocity="3" />
  </joint>
  <link
    name="knee_RL_link">
    <inertial>
      <origin
        xyz="0.0164835065607598 0.00142729560882487 -0.153846648020305"
        rpy="0 0 0" />
      <mass
        value="0.367874494498672" />
      <inertia
        ixx="0.00262374429195376"
        ixy="-1.08195805856552E-09"
        ixz="0.000246070252833701"
        iyy="0.00268159880702633"
        iyz="-4.03703765123899E-09"
        izz="7.25195050246535E-05" />
    </inertial>
    <visual>
      <origin
        xyz="0 0 0"
        rpy="0 0 0" />
      <geometry>
        <mesh
          filename="package://scotty_description/meshes/knee_RL_link.STL" />
      </geometry>
      <material
        name="">
        <color
          rgba="0.898039215686275 0.917647058823529 0.929411764705882 1" />
      </material>
    </visual>
    <collision>
      <origin
        xyz="0 0 0"
        rpy="0 0 0" />
      <geometry>
        <mesh
          filename="package://scotty_description/meshes/knee_RL_link.STL" />
      </geometry>
    </collision>
  </link>
  <joint
    name="knee_RL_joint"
    type="revolute">
    <origin
      xyz="0 0.087405 -0.3"
      rpy="0 0 0" />
    <parent
      link="hip_RL_link" />
    <child
      link="knee_RL_link" />
    <axis
      xyz="0 -1 0" />
    <limit
      lower="-2.5"
      upper="0"
      effort="50"
      velocity="3" />
  </joint>
</robot>